[2022-02-25T21:06:29Z] DEBUG    - Logging set up successfully
[2022-02-25T21:06:29Z] DEBUG    - Running generate: Namespace(command=<function generate at 0x11bb43430>, endpoint_url=None, region=None, subparser_name='generate', target_schemas=[], verbose=0, version=False)
[2022-02-25T21:06:29Z] DEBUG    - Root directory: /Volumes/workplace/aws-cloudformation-resource-providers-redshiftserverless
[2022-02-25T21:06:29Z] DEBUG    - Loading project file '/Volumes/workplace/aws-cloudformation-resource-providers-redshiftserverless/.rpdk-config'
[2022-02-25T21:06:29Z] DEBUG    - Project file /Volumes/workplace/aws-cloudformation-resource-providers-redshiftserverless/.rpdk-config not found. Have you run 'init' or in a wrong directory?
Traceback (most recent call last):
  File "/Volumes/workplace/python-venv-cfn-migration-dev/lib/python3.8/site-packages/rpdk/core/project.py", line 562, in load
    self.load_settings()
  File "/Volumes/workplace/python-venv-cfn-migration-dev/lib/python3.8/site-packages/rpdk/core/project.py", line 234, in load_settings
    with self.settings_path.open("r", encoding="utf-8") as f:
  File "/Library/Developer/CommandLineTools/Library/Frameworks/Python3.framework/Versions/3.8/lib/python3.8/pathlib.py", line 1213, in open
    return io.open(self, mode, buffering, encoding, errors, newline,
  File "/Library/Developer/CommandLineTools/Library/Frameworks/Python3.framework/Versions/3.8/lib/python3.8/pathlib.py", line 1069, in _opener
    return self._accessor.open(self, flags, mode)
FileNotFoundError: [Errno 2] No such file or directory: '/Volumes/workplace/aws-cloudformation-resource-providers-redshiftserverless/.rpdk-config'
[2022-02-25T21:06:29Z] DEBUG    - Caught exit recommendation
Traceback (most recent call last):
  File "/Volumes/workplace/python-venv-cfn-migration-dev/lib/python3.8/site-packages/rpdk/core/project.py", line 562, in load
    self.load_settings()
  File "/Volumes/workplace/python-venv-cfn-migration-dev/lib/python3.8/site-packages/rpdk/core/project.py", line 234, in load_settings
    with self.settings_path.open("r", encoding="utf-8") as f:
  File "/Library/Developer/CommandLineTools/Library/Frameworks/Python3.framework/Versions/3.8/lib/python3.8/pathlib.py", line 1213, in open
    return io.open(self, mode, buffering, encoding, errors, newline,
  File "/Library/Developer/CommandLineTools/Library/Frameworks/Python3.framework/Versions/3.8/lib/python3.8/pathlib.py", line 1069, in _opener
    return self._accessor.open(self, flags, mode)
FileNotFoundError: [Errno 2] No such file or directory: '/Volumes/workplace/aws-cloudformation-resource-providers-redshiftserverless/.rpdk-config'

The above exception was the direct cause of the following exception:

Traceback (most recent call last):
  File "/Volumes/workplace/python-venv-cfn-migration-dev/lib/python3.8/site-packages/rpdk/core/cli.py", line 100, in main
    args.command(args)
  File "/Volumes/workplace/python-venv-cfn-migration-dev/lib/python3.8/site-packages/rpdk/core/generate.py", line 14, in generate
    project.load()
  File "/Volumes/workplace/python-venv-cfn-migration-dev/lib/python3.8/site-packages/rpdk/core/project.py", line 564, in load
    self._raise_invalid_project(
  File "/Volumes/workplace/python-venv-cfn-migration-dev/lib/python3.8/site-packages/rpdk/core/project.py", line 229, in _raise_invalid_project
    raise InvalidProjectError(msg) from e
rpdk.core.exceptions.InvalidProjectError: Project file /Volumes/workplace/aws-cloudformation-resource-providers-redshiftserverless/.rpdk-config not found. Have you run 'init' or in a wrong directory?
[2022-02-25T21:06:29Z] CRITICAL - Project file /Volumes/workplace/aws-cloudformation-resource-providers-redshiftserverless/.rpdk-config not found. Have you run 'init' or in a wrong directory?
[2022-02-25T21:37:22Z] DEBUG    - Logging set up successfully
[2022-02-25T21:37:22Z] DEBUG    - Running generate: Namespace(command=<function generate at 0x1173463a0>, endpoint_url=None, region=None, subparser_name='generate', target_schemas=[], verbose=0, version=False)
[2022-02-25T21:37:22Z] DEBUG    - Root directory: /Volumes/workplace/aws-cloudformation-resource-providers-redshiftserverless
[2022-02-25T21:37:22Z] DEBUG    - Loading project file '/Volumes/workplace/aws-cloudformation-resource-providers-redshiftserverless/.rpdk-config'
[2022-02-25T21:37:22Z] DEBUG    - Project file /Volumes/workplace/aws-cloudformation-resource-providers-redshiftserverless/.rpdk-config not found. Have you run 'init' or in a wrong directory?
Traceback (most recent call last):
  File "/Volumes/workplace/python-venv-cfn-migration-dev/lib/python3.8/site-packages/rpdk/core/project.py", line 562, in load
    self.load_settings()
  File "/Volumes/workplace/python-venv-cfn-migration-dev/lib/python3.8/site-packages/rpdk/core/project.py", line 234, in load_settings
    with self.settings_path.open("r", encoding="utf-8") as f:
  File "/Library/Developer/CommandLineTools/Library/Frameworks/Python3.framework/Versions/3.8/lib/python3.8/pathlib.py", line 1213, in open
    return io.open(self, mode, buffering, encoding, errors, newline,
  File "/Library/Developer/CommandLineTools/Library/Frameworks/Python3.framework/Versions/3.8/lib/python3.8/pathlib.py", line 1069, in _opener
    return self._accessor.open(self, flags, mode)
FileNotFoundError: [Errno 2] No such file or directory: '/Volumes/workplace/aws-cloudformation-resource-providers-redshiftserverless/.rpdk-config'
[2022-02-25T21:37:22Z] DEBUG    - Caught exit recommendation
Traceback (most recent call last):
  File "/Volumes/workplace/python-venv-cfn-migration-dev/lib/python3.8/site-packages/rpdk/core/project.py", line 562, in load
    self.load_settings()
  File "/Volumes/workplace/python-venv-cfn-migration-dev/lib/python3.8/site-packages/rpdk/core/project.py", line 234, in load_settings
    with self.settings_path.open("r", encoding="utf-8") as f:
  File "/Library/Developer/CommandLineTools/Library/Frameworks/Python3.framework/Versions/3.8/lib/python3.8/pathlib.py", line 1213, in open
    return io.open(self, mode, buffering, encoding, errors, newline,
  File "/Library/Developer/CommandLineTools/Library/Frameworks/Python3.framework/Versions/3.8/lib/python3.8/pathlib.py", line 1069, in _opener
    return self._accessor.open(self, flags, mode)
FileNotFoundError: [Errno 2] No such file or directory: '/Volumes/workplace/aws-cloudformation-resource-providers-redshiftserverless/.rpdk-config'

The above exception was the direct cause of the following exception:

Traceback (most recent call last):
  File "/Volumes/workplace/python-venv-cfn-migration-dev/lib/python3.8/site-packages/rpdk/core/cli.py", line 100, in main
    args.command(args)
  File "/Volumes/workplace/python-venv-cfn-migration-dev/lib/python3.8/site-packages/rpdk/core/generate.py", line 14, in generate
    project.load()
  File "/Volumes/workplace/python-venv-cfn-migration-dev/lib/python3.8/site-packages/rpdk/core/project.py", line 564, in load
    self._raise_invalid_project(
  File "/Volumes/workplace/python-venv-cfn-migration-dev/lib/python3.8/site-packages/rpdk/core/project.py", line 229, in _raise_invalid_project
    raise InvalidProjectError(msg) from e
rpdk.core.exceptions.InvalidProjectError: Project file /Volumes/workplace/aws-cloudformation-resource-providers-redshiftserverless/.rpdk-config not found. Have you run 'init' or in a wrong directory?
[2022-02-25T21:37:22Z] CRITICAL - Project file /Volumes/workplace/aws-cloudformation-resource-providers-redshiftserverless/.rpdk-config not found. Have you run 'init' or in a wrong directory?
